io_and_status_controller:
  artifacts:
    io_and_status_controller: # change to exector name
      node: io_and_status_controller
      subscribers:
        "parameter_events":
          type: "rcl_interfaces/msg/ParameterEvent"
      publishers:
        "~/io_states":
          type: "ur_msgs/msg/IOStates"
        "~/robot_mode":
          type: "ur_dashboard_msgs/msg/RobotMode"
        "~/robot_program_running":
          type: "std_msgs/msg/Bool"
        "~/safety_mode":
          type: "ur_dashboard_msgs/msg/SafetyMode"
        "~/tool_data":
          type: "ur_msgs/msg/ToolDataMsg"
        "~/transition_event":
          type: "lifecycle_msgs/msg/TransitionEvent"
        "parameter_events":
          type: "rcl_interfaces/msg/ParameterEvent"
        "rosout":
          type: "rcl_interfaces/msg/Log"
      serviceservers:
        "~/describe_parameters":
          type: "rcl_interfaces/srv/DescribeParameters"
        "~/get_parameter_types":
          type: "rcl_interfaces/srv/GetParameterTypes"
        "~/get_parameters":
          type: "rcl_interfaces/srv/GetParameters"
        "~/hand_back_control":
          type: "std_srvs/srv/Trigger"
        "~/list_parameters":
          type: "rcl_interfaces/srv/ListParameters"
        "~/resend_robot_program":
          type: "std_srvs/srv/Trigger"
        "~/set_io":
          type: "ur_msgs/srv/SetIO"
        "~/set_parameters":
          type: "rcl_interfaces/srv/SetParameters"
        "~/set_parameters_atomically":
          type: "rcl_interfaces/srv/SetParametersAtomically"
        "~/set_payload":
          type: "ur_msgs/srv/SetPayload"
        "~/set_speed_slider":
          type: "ur_msgs/srv/SetSpeedSliderFraction"
        "~/zero_ftsensor":
          type: "std_srvs/srv/Trigger"
      parameters:
        "check_io_successfull_retries":
          type: Integer
          value: 10
        "robot_description":
          type: String
          value: "<?xml version="1.0" ?> <!-- =================================================================================== --> <!-- |    This document was autogenerated by xacro from /home/admin326/workspaces/ros2_ws/install/ur5e_cell_description/share/ur5e_cell_description/urdf/workcell.urdf.xacro | --> <!-- |    EDITING THIS FILE BY HAND IS NOT RECOMMENDED                                 | --> <!-- =================================================================================== --> <robot name="ur5e_workcell"> <!-- Specify some standard inertial calculations https://en.wikipedia.org/wiki/List_of_moments_of_inertia --> <!-- These make use of xacro's mathematical functionality --> <!-- Base UR robot series xacro macro.
NOTE this is NOT a URDF. It cannot directly be loaded by consumers expecting a flattened '.urdf' file. See the top-level '.xacro' for that (but note that .xacro must still be processed by the xacro command).
This file models the base kinematic chain of a UR robot, which then gets parameterised by various configuration files to convert it into a UR3(e), UR5(e), UR10(e) or UR16e.
NOTE the default kinematic parameters (i.e., link lengths, frame locations, offsets, etc) do not correspond to any particular robot. They are defaults only. There WILL be non-zero offsets between the Forward Kinematics results in TF (i.e., robot_state_publisher) and the values reported by the Teach Pendant.
For accurate (and robot-specific) transforms, the 'kinematics_parameters_file' parameter MUST point to a .yaml file containing the appropriate values for the targeted robot.
If using the UniversalRobots/Universal_Robots_ROS_Driver, follow the steps described in the readme of that repository to extract the kinematic calibration from the controller and generate the required .yaml file.
Main author of the migration to yaml configs Ludovic Delval.
Contributors to previous versions (in no particular order)
- Denis Stogl - Lovro Ivanov - Felix Messmer - Kelsey Hawkins - Wim Meeussen - Shaun Edwards - Nadia Hammoudeh Garcia - Dave Hershberger - G. vd. Hoorn - Philip Long - Dave Coleman - Miguel Prada - Mathias Luedtke - Marcel Schnirring - Felix von Drigalski - Felix Exner - Jimmy Da Silva - Ajit Krisshna N L - Muhammad Asif Rana --> <!-- NOTE the macro defined in this file is NOT part of the public API of this package. Users CANNOT rely on this file being available, or stored in this location. Nor can they rely on the existence of the macro. --> <material name="aluminum"> <color rgba="0.5 0.5 0.5 1"/> </material> <material name="plastic"> <color rgba="0.1 0.1 0.1 1"/> </material> <!-- Add world link --> <link name="world"/> <material name="gray"> <color rgba="0.6 0.8 0.8 1"/> </material> <link name="visuals_link"> <visual> <geometry> <mesh filename="package://ur5e_cell_description/meshes/Assembly_new.STL" scale="0.001 0.001 0.001"/> </geometry> <material name="gray"/> </visual> </link> <link name="shield_front_link"> <collision> <origin rpy="0 0 0" xyz="0 0 0"/> <geometry> <box size="1.44 0.03 1.16"/> </geometry> <material name="gray"/> </collision> <inertial> <origin rpy="0 0 0" xyz="0 0 0"/> <mass value="5"/> <inertia ixx="0.5610416666666665" ixy="0.0" ixz="0.0" iyy="1.4246666666666665" iyz="0.0" izz="0.8643749999999999"/> </inertial> </link> <link name="shield_rear_link"> <collision> <origin rpy="0 0 0 " xyz="0 0 0"/> <geometry> <box size="1.44 0.03 1.16"/> </geometry> <material name="gray"/> </collision> <inertial> <origin rpy="0 0 0" xyz="0 0 0"/> <mass value="5"/> <inertia ixx="0.5610416666666665" ixy="0.0" ixz="0.0" iyy="1.4246666666666665" iyz="0.0" izz="0.8643749999999999"/> </inertial> </link> <link name="shield_right_link"> <collision> <origin rpy="0 0 0" xyz="0 0 0"/> <geometry> <box size="0.03 0.94 1.16"/> </geometry> <material name="gray"/> </collision> <inertial> <origin rpy="0 0 0" xyz="0 0 0"/> <mass value="5"/> <inertia ixx="0.9288333333333331" ixy="0.0" ixz="0.0" iyy="0.5610416666666665" iyz="0.0" izz="0.3685416666666666"/> </inertial> </link> <link name="shield_left_link"> <collision> <origin rpy="0 0 0" xyz="0 0 0"/> <geometry> <box size="0.03 0.94 1.16"/> </geometry> <material name="gray"/> </collision> <inertial> <origin rpy="0 0 0" xyz="0 0 0"/> <mass value="5"/> <inertia ixx="0.9288333333333331" ixy="0.0" ixz="0.0" iyy="0.5610416666666665" iyz="0.0" izz="0.3685416666666666"/> </inertial> </link> <link name="robotcell_base_link"> <collision> <origin rpy="0 0 0" xyz="0 0 0.495"/> <geometry> <box size="1.44 0.94 0.99"/> </geometry> <material name="gray"/> </collision> <inertial> <origin rpy="0 0 0" xyz="0 0 0"/> <mass value="70"/> <inertia ixx="10.871583333333332" ixy="0.0" ixz="0.0" iyy="17.81325" iyz="0.0" izz="17.25033333333333"/> </inertial> </link> <link name="robot_link"/> <joint name="robotcell_base_to_visual" type="fixed"> <parent link="robotcell_base_link"/> <child link="visuals_link"/> <origin rpy="0 0 1.5707963267948966" xyz="0.75 -0.5 0"/> </joint> <joint name="robotcell_base_to_front_joint" type="fixed"> <parent link="robotcell_base_link"/> <child link="shield_front_link"/> <origin rpy="0 0 0" xyz="0 0.45499999999999996 1.5699999999999998"/> </joint> <joint name="robotcell_base_to_rear" type="fixed"> <parent link="robotcell_base_link"/> <child link="shield_rear_link"/> <origin rpy="0 0 0" xyz="0 -0.45499999999999996 1.5699999999999998"/> </joint> <joint name="robotcell_base_to_left" type="fixed"> <parent link="robotcell_base_link"/> <child link="shield_left_link"/> <origin rpy="0 0 0" xyz="-0.705 0 1.5699999999999998"/> </joint> <joint name="robotcell_base_to_right" type="fixed"> <parent link="robotcell_base_link"/> <child link="shield_right_link"/> <origin rpy="0 0 0" xyz="0.705 0 1.5699999999999998"/> </joint> <joint name="robot_cell_base_joint" type="fixed"> <parent link="world"/> <child link="robotcell_base_link"/> <origin rpy="0 0 0" xyz="0 0 0"/> </joint> <joint name="robot_cell_base_to_robot_link" type="fixed"> <parent link="robotcell_base_link"/> <child link="robot_link"/> <origin rpy="0 0 0" xyz="0.42 0.02 0.99"/> </joint> <ros2_control name="ur5e" type="system"> <hardware> <plugin>ur_robot_driver/URPositionHardwareInterface</plugin> <param name="robot_ip">192.168.56.2</param> <param name="script_filename">/opt/ros/humble/share/ur_client_library/resources/external_control.urscript</param> <param name="output_recipe_filename">/opt/ros/humble/share/ur_robot_driver/resources/rtde_output_recipe.txt</param> <param name="input_recipe_filename">/opt/ros/humble/share/ur_robot_driver/resources/rtde_input_recipe.txt</param> <param name="headless_mode">False</param> <param name="reverse_port">50001</param> <param name="script_sender_port">50002</param> <param name="reverse_ip">0.0.0.0</param> <param name="script_command_port">50004</param> <param name="trajectory_port">50003</param> <param name="tf_prefix"></param> <param name="non_blocking_read">True</param> <param name="servoj_gain">2000</param> <param name="servoj_lookahead_time">0.03</param> <param name="use_tool_communication">False</param> <param name="kinematics/hash">calib_11698609823524220358</param> <param name="tool_voltage">0</param> <param name="tool_parity">0</param> <param name="tool_baud_rate">115200</param> <param name="tool_stop_bits">1</param> <param name="tool_rx_idle_chars">1.5</param> <param name="tool_tx_idle_chars">3.5</param> <param name="tool_device_name">/tmp/ttyUR</param> <param name="tool_tcp_port">54321</param> <param name="keep_alive_count">2</param> </hardware> <joint name="shoulder_pan_joint"> <command_interface name="position"> <param name="min">{-2*pi}</param> <param name="max">{2*pi}</param> </command_interface> <command_interface name="velocity"> <param name="min">-3.15</param> <param name="max">3.15</param> </command_interface> <state_interface name="position"> <!-- initial position for the FakeSystem and simulation --> <param name="initial_value">-1.57</param> </state_interface> <state_interface name="velocity"/> <state_interface name="effort"/> </joint> <joint name="shoulder_lift_joint"> <command_interface name="position"> <param name="min">{-2*pi}</param> <param name="max">{2*pi}</param> </command_interface> <command_interface name="velocity"> <param name="min">-3.15</param> <param name="max">3.15</param> </command_interface> <state_interface name="position"> <!-- initial position for the FakeSystem and simulation --> <param name="initial_value">-1.57</param> </state_interface> <state_interface name="velocity"/> <state_interface name="effort"/> </joint> <joint name="elbow_joint"> <command_interface name="position"> <param name="min">{-pi}</param> <param name="max">{pi}</param> </command_interface> <command_interface name="velocity"> <param name="min">-3.15</param> <param name="max">3.15</param> </command_interface> <state_interface name="position"> <!-- initial position for the FakeSystem and simulation --> <param name="initial_value">-1.57</param> </state_interface> <state_interface name="velocity"/> <state_interface name="effort"/> </joint> <joint name="wrist_1_joint"> <command_interface name="position"> <param name="min">{-2*pi}</param> <param name="max">{2*pi}</param> </command_interface> <command_interface name="velocity"> <param name="min">-3.2</param> <param name="max">3.2</param> </command_interface> <state_interface name="position"> <!-- initial position for the FakeSystem and simulation --> <param name="initial_value">-1.57</param> </state_interface> <state_interface name="velocity"/> <state_interface name="effort"/> </joint> <joint name="wrist_2_joint"> <command_interface name="position"> <param name="min">{-2*pi}</param> <param name="max">{2*pi}</param> </command_interface> <command_interface name="velocity"> <param name="min">-3.2</param> <param name="max">3.2</param> </command_interface> <state_interface name="position"> <!-- initial position for the FakeSystem and simulation --> <param name="initial_value">1.57</param> </state_interface> <state_interface name="velocity"/> <state_interface name="effort"/> </joint> <joint name="wrist_3_joint"> <command_interface name="position"> <param name="min">{-2*pi}</param> <param name="max">{2*pi}</param> </command_interface> <command_interface name="velocity"> <param name="min">-3.2</param> <param name="max">3.2</param> </command_interface> <state_interface name="position"> <!-- initial position for the FakeSystem and simulation --> <param name="initial_value">0.0</param> </state_interface> <state_interface name="velocity"/> <state_interface name="effort"/> </joint> <sensor name="tcp_fts_sensor"> <state_interface name="force.x"/> <state_interface name="force.y"/> <state_interface name="force.z"/> <state_interface name="torque.x"/> <state_interface name="torque.y"/> <state_interface name="torque.z"/> </sensor> <!-- NOTE The following are joints used only for testing with fake hardware and will change in the future --> <gpio name="speed_scaling"> <state_interface name="speed_scaling_factor"/> <param name="initial_speed_scaling_factor">1</param> <command_interface name="target_speed_fraction_cmd"/> <command_interface name="target_speed_fraction_async_success"/> </gpio> <gpio name="gpio"> <command_interface name="standard_digital_output_cmd_0"/> <command_interface name="standard_digital_output_cmd_1"/> <command_interface name="standard_digital_output_cmd_2"/> <command_interface name="standard_digital_output_cmd_3"/> <command_interface name="standard_digital_output_cmd_4"/> <command_interface name="standard_digital_output_cmd_5"/> <command_interface name="standard_digital_output_cmd_6"/> <command_interface name="standard_digital_output_cmd_7"/> <command_interface name="standard_digital_output_cmd_8"/> <command_interface name="standard_digital_output_cmd_9"/> <command_interface name="standard_digital_output_cmd_10"/> <command_interface name="standard_digital_output_cmd_11"/> <command_interface name="standard_digital_output_cmd_12"/> <command_interface name="standard_digital_output_cmd_13"/> <command_interface name="standard_digital_output_cmd_14"/> <command_interface name="standard_digital_output_cmd_15"/> <command_interface name="standard_digital_output_cmd_16"/> <command_interface name="standard_digital_output_cmd_17"/> <command_interface name="standard_analog_output_cmd_0"/> <command_interface name="standard_analog_output_cmd_1"/> <command_interface name="tool_voltage_cmd"/> <command_interface name="io_async_success"/> <state_interface name="digital_output_0"/> <state_interface name="digital_output_1"/> <state_interface name="digital_output_2"/> <state_interface name="digital_output_3"/> <state_interface name="digital_output_4"/> <state_interface name="digital_output_5"/> <state_interface name="digital_output_6"/> <state_interface name="digital_output_7"/> <state_interface name="digital_output_8"/> <state_interface name="digital_output_9"/> <state_interface name="digital_output_10"/> <state_interface name="digital_output_11"/> <state_interface name="digital_output_12"/> <state_interface name="digital_output_13"/> <state_interface name="digital_output_14"/> <state_interface name="digital_output_15"/> <state_interface name="digital_output_16"/> <state_interface name="digital_output_17"/> <state_interface name="digital_input_0"/> <state_interface name="digital_input_1"/> <state_interface name="digital_input_2"/> <state_interface name="digital_input_3"/> <state_interface name="digital_input_4"/> <state_interface name="digital_input_5"/> <state_interface name="digital_input_6"/> <state_interface name="digital_input_7"/> <state_interface name="digital_input_8"/> <state_interface name="digital_input_9"/> <state_interface name="digital_input_10"/> <state_interface name="digital_input_11"/> <state_interface name="digital_input_12"/> <state_interface name="digital_input_13"/> <state_interface name="digital_input_14"/> <state_interface name="digital_input_15"/> <state_interface name="digital_input_16"/> <state_interface name="digital_input_17"/> <state_interface name="standard_analog_output_0"/> <state_interface name="standard_analog_output_1"/> <state_interface name="standard_analog_input_0"/> <state_interface name="standard_analog_input_1"/> <state_interface name="analog_io_type_0"/> <state_interface name="analog_io_type_1"/> <state_interface name="analog_io_type_2"/> <state_interface name="analog_io_type_3"/> <state_interface name="tool_mode"/> <state_interface name="tool_output_voltage"/> <state_interface name="tool_output_current"/> <state_interface name="tool_temperature"/> <state_interface name="tool_analog_input_0"/> <state_interface name="tool_analog_input_1"/> <state_interface name="tool_analog_input_type_0"/> <state_interface name="tool_analog_input_type_1"/> <state_interface name="robot_mode"/> <state_interface name="robot_status_bit_0"/> <state_interface name="robot_status_bit_1"/> <state_interface name="robot_status_bit_2"/> <state_interface name="robot_status_bit_3"/> <state_interface name="safety_mode"/> <state_interface name="safety_status_bit_0"/> <state_interface name="safety_status_bit_1"/> <state_interface name="safety_status_bit_2"/> <state_interface name="safety_status_bit_3"/> <state_interface name="safety_status_bit_4"/> <state_interface name="safety_status_bit_5"/> <state_interface name="safety_status_bit_6"/> <state_interface name="safety_status_bit_7"/> <state_interface name="safety_status_bit_8"/> <state_interface name="safety_status_bit_9"/> <state_interface name="safety_status_bit_10"/> <state_interface name="program_running"/> </gpio> <gpio name="payload"> <command_interface name="mass"/> <command_interface name="cog.x"/> <command_interface name="cog.y"/> <command_interface name="cog.z"/> <command_interface name="payload_async_success"/> </gpio> <gpio name="resend_robot_program"> <command_interface name="resend_robot_program_cmd"/> <command_interface name="resend_robot_program_async_success"/> </gpio> <gpio name="hand_back_control"> <command_interface name="hand_back_control_cmd"/> <command_interface name="hand_back_control_async_success"/> </gpio> <gpio name="zero_ftsensor"> <command_interface name="zero_ftsensor_cmd"/> <command_interface name="zero_ftsensor_async_success"/> </gpio> <gpio name="system_interface"> <state_interface name="initialized"/> </gpio> </ros2_control> <!-- Add URDF transmission elements (for ros_control) --> <!--<xacro:ur_arm_transmission prefix="${prefix}" hw_interface="${transmission_hw_interface}" />--> <!-- Placeholder for ros2_control transmission which don't yet exist --> <!-- links -  main serial chain --> <link name="base_link"/> <link name="base_link_inertia"> <visual> <origin rpy="0 0 3.141592653589793" xyz="0 0 0"/> <geometry> <mesh filename="package://ur_description/meshes/ur5e/visual/base.dae"/> </geometry> </visual> <collision> <origin rpy="0 0 3.141592653589793" xyz="0 0 0"/> <geometry> <mesh filename="package://ur_description/meshes/ur5e/collision/base.stl"/> </geometry> </collision> <inertial> <mass value="4.0"/> <origin rpy="0 0 0" xyz="0 0 0"/> <inertia ixx="0.00443333156" ixy="0.0" ixz="0.0" iyy="0.00443333156" iyz="0.0" izz="0.0072"/> </inertial> </link> <link name="shoulder_link"> <visual> <origin rpy="0 0 3.141592653589793" xyz="0 0 0"/> <geometry> <mesh filename="package://ur_description/meshes/ur5e/visual/shoulder.dae"/> </geometry> </visual> <collision> <origin rpy="0 0 3.141592653589793" xyz="0 0 0"/> <geometry> <mesh filename="package://ur_description/meshes/ur5e/collision/shoulder.stl"/> </geometry> </collision> <inertial> <mass value="3.7"/> <origin rpy="0 0 0" xyz="0 0 0"/> <inertia ixx="0.010267495893" ixy="0.0" ixz="0.0" iyy="0.010267495893" iyz="0.0" izz="0.00666"/> </inertial> </link> <link name="upper_arm_link"> <visual> <origin rpy="1.5707963267948966 0 -1.5707963267948966" xyz="0 0 0.138"/> <geometry> <mesh filename="package://ur_description/meshes/ur5e/visual/upperarm.dae"/> </geometry> </visual> <collision> <origin rpy="1.5707963267948966 0 -1.5707963267948966" xyz="0 0 0.138"/> <geometry> <mesh filename="package://ur_description/meshes/ur5e/collision/upperarm.stl"/> </geometry> </collision> <inertial> <mass value="8.393"/> <origin rpy="0 1.5707963267948966 0" xyz="-0.2125 0.0 0.138"/> <inertia ixx="0.1338857818623325" ixy="0.0" ixz="0.0" iyy="0.1338857818623325" iyz="0.0" izz="0.0151074"/> </inertial> </link> <link name="forearm_link"> <visual> <origin rpy="1.5707963267948966 0 -1.5707963267948966" xyz="0 0 0.007"/> <geometry> <mesh filename="package://ur_description/meshes/ur5e/visual/forearm.dae"/> </geometry> </visual> <collision> <origin rpy="1.5707963267948966 0 -1.5707963267948966" xyz="0 0 0.007"/> <geometry> <mesh filename="package://ur_description/meshes/ur5e/collision/forearm.stl"/> </geometry> </collision> <inertial> <mass value="2.275"/> <origin rpy="0 1.5707963267948966 0" xyz="-0.1961 0.0 0.007"/> <inertia ixx="0.031209355099586295" ixy="0.0" ixz="0.0" iyy="0.031209355099586295" iyz="0.0" izz="0.004095"/> </inertial> </link> <link name="wrist_1_link"> <visual> <origin rpy="1.5707963267948966 0 0" xyz="0 0 -0.127"/> <geometry> <mesh filename="package://ur_description/meshes/ur5e/visual/wrist1.dae"/> </geometry> </visual> <collision> <origin rpy="1.5707963267948966 0 0" xyz="0 0 -0.127"/> <geometry> <mesh filename="package://ur_description/meshes/ur5e/collision/wrist1.stl"/> </geometry> </collision> <inertial> <mass value="1.219"/> <origin rpy="0 0 0" xyz="0 0 0"/> <inertia ixx="0.0025598989760400002" ixy="0.0" ixz="0.0" iyy="0.0025598989760400002" iyz="0.0" izz="0.0021942"/> </inertial> </link> <link name="wrist_2_link"> <visual> <origin rpy="0 0 0" xyz="0 0 -0.0997"/> <geometry> <mesh filename="package://ur_description/meshes/ur5e/visual/wrist2.dae"/> </geometry> </visual> <collision> <origin rpy="0 0 0" xyz="0 0 -0.0997"/> <geometry> <mesh filename="package://ur_description/meshes/ur5e/collision/wrist2.stl"/> </geometry> </collision> <inertial> <mass value="1.219"/> <origin rpy="0 0 0" xyz="0 0 0"/> <inertia ixx="0.0025598989760400002" ixy="0.0" ixz="0.0" iyy="0.0025598989760400002" iyz="0.0" izz="0.0021942"/> </inertial> </link> <link name="wrist_3_link"> <visual> <origin rpy="1.5707963267948966 0 0" xyz="0 0 -0.0989"/> <geometry> <mesh filename="package://ur_description/meshes/ur5e/visual/wrist3.dae"/> </geometry> </visual> <collision> <origin rpy="1.5707963267948966 0 0" xyz="0 0 -0.0989"/> <geometry> <mesh filename="package://ur_description/meshes/ur5e/collision/wrist3.stl"/> </geometry> </collision> <inertial> <mass value="0.1879"/> <origin rpy="0 0 0" xyz="0.0 0.0 -0.0229"/> <inertia ixx="9.890410052167731e-05" ixy="0.0" ixz="0.0" iyy="9.890410052167731e-05" iyz="0.0" izz="0.0001321171875"/> </inertial> </link> <!-- base_joint fixes base_link to the environment --> <joint name="base_joint" type="fixed"> <origin rpy="0 0 1.5707963267948966" xyz="0 0 0"/> <parent link="robot_link"/> <child link="base_link"/> </joint> <!-- joints - main serial chain --> <joint name="base_link-base_link_inertia" type="fixed"> <parent link="base_link"/> <child link="base_link_inertia"/> <!-- 'base_link' is REP-103 aligned (so X+ forward), while the internal frames of the robot/controller have X+ pointing backwards. Use the joint between 'base_link' and 'base_link_inertia' (a dummy link/frame) to introduce the necessary rotation over Z (of pi rad). --> <origin rpy="0 0 3.141592653589793" xyz="0 0 0"/> </joint> <joint name="shoulder_pan_joint" type="revolute"> <parent link="base_link_inertia"/> <child link="shoulder_link"/> <origin rpy="0 0 4.129148531428761e-08" xyz="0 0 0.16257940898924925"/> <axis xyz="0 0 1"/> <limit effort="150.0" lower="-6.283185307179586" upper="6.283185307179586" velocity="3.141592653589793"/> <safety_controller k_position="20" k_velocity="0.0" soft_lower_limit="-6.133185307179586" soft_upper_limit="6.133185307179586"/> <dynamics damping="0" friction="0"/> </joint> <joint name="shoulder_lift_joint" type="revolute"> <parent link="shoulder_link"/> <child link="upper_arm_link"/> <origin rpy="1.569869765796217 0 5.036318121915316e-06" xyz="4.928395535654581e-05 0 0"/> <axis xyz="0 0 1"/> <limit effort="150.0" lower="-6.283185307179586" upper="6.283185307179586" velocity="3.141592653589793"/> <safety_controller k_position="20" k_velocity="0.0" soft_lower_limit="-6.133185307179586" soft_upper_limit="6.133185307179586"/> <dynamics damping="0" friction="0"/> </joint> <joint name="elbow_joint" type="revolute"> <parent link="upper_arm_link"/> <child link="forearm_link"/> <origin rpy="3.1392013464244997 3.1391688059969463 -3.1415916373618824" xyz="-0.4254523763434618 0 0"/> <axis xyz="0 0 1"/> <limit effort="150.0" lower="-3.141592653589793" upper="0.0" velocity="3.141592653589793"/> <safety_controller k_position="20" k_velocity="0.0" soft_lower_limit="-2.991592653589793" soft_upper_limit="-0.15"/> <dynamics damping="0" friction="0"/> </joint> <joint name="wrist_1_joint" type="revolute"> <parent link="forearm_link"/> <child link="wrist_1_link"/> <origin rpy="3.1407543838911054 -3.1393367089449136 3.141588769544439" xyz="-0.3925179308036957 0.00011209320964041982 0.13371971283234207"/> <axis xyz="0 0 1"/> <limit effort="28.0" lower="-6.283185307179586" upper="6.283185307179586" velocity="3.141592653589793"/> <safety_controller k_position="20" k_velocity="0.0" soft_lower_limit="-6.133185307179586" soft_upper_limit="6.133185307179586"/> <dynamics damping="0" friction="0"/> </joint> <joint name="wrist_2_joint" type="revolute"> <parent link="wrist_1_link"/> <child link="wrist_2_link"/> <origin rpy="1.5696737491576425 0 1.6248900383403209e-06" xyz="-5.074257472996066e-05 -0.09963845508736849 0.0001118519484761866"/> <axis xyz="0 0 1"/> <limit effort="28.0" lower="-6.283185307179586" upper="6.283185307179586" velocity="3.141592653589793"/> <safety_controller k_position="20" k_velocity="0.0" soft_lower_limit="-6.133185307179586" soft_upper_limit="6.133185307179586"/> <dynamics damping="0" friction="0"/> </joint> <joint name="wrist_3_joint" type="revolute"> <parent link="wrist_2_link"/> <child link="wrist_3_link"/> <origin rpy="1.5724268955944378 3.141592653589793 3.141592586202488" xyz="0.00015530393797499986 0.09948201802868764 0.00016221241847401644"/> <axis xyz="0 0 1"/> <limit effort="28.0" lower="-6.283185307179586" upper="6.283185307179586" velocity="3.141592653589793"/> <safety_controller k_position="20" k_velocity="0.0" soft_lower_limit="-6.133185307179586" soft_upper_limit="6.133185307179586"/> <dynamics damping="0" friction="0"/> </joint> <link name="ft_frame"/> <joint name="wrist_3_link-ft_frame" type="fixed"> <parent link="wrist_3_link"/> <child link="ft_frame"/> <origin rpy="3.141592653589793 0 0" xyz="0 0 0"/> </joint> <!-- ROS-Industrial 'base' frame - base_link to UR 'Base' Coordinates transform --> <link name="base"/> <joint name="base_link-base_fixed_joint" type="fixed"> <!-- Note the rotation over Z of pi radians - as base_link is REP-103 aligned (i.e., has X+ forward, Y+ left and Z+ up), this is needed to correctly align 'base' with the 'Base' coordinate system of the UR controller. --> <origin rpy="0 0 3.141592653589793" xyz="0 0 0"/> <parent link="base_link"/> <child link="base"/> </joint> <!-- ROS-Industrial 'flange' frame - attachment point for EEF models --> <link name="flange"/> <joint name="wrist_3-flange" type="fixed"> <parent link="wrist_3_link"/> <child link="flange"/> <origin rpy="0 -1.5707963267948966 -1.5707963267948966" xyz="0 0 0"/> </joint> <!-- ROS-Industrial 'tool0' frame - all-zeros tool frame --> <link name="tool0"/> <joint name="flange-tool0" type="fixed"> <!-- default toolframe - X+ left, Y+ up, Z+ front --> <origin rpy="1.5707963267948966 0 1.5707963267948966" xyz="0 0 0"/> <parent link="flange"/> <child link="tool0"/> </joint> <!-- Specify some standard inertial calculations https://en.wikipedia.org/wiki/List_of_moments_of_inertia --> <!-- These make use of xacro's mathematical functionality --> <material name="blue"> <color rgba="0 0.2 1 1"/> </material> <material name="green"> <color rgba="0 0.9 0.3 1"/> </material> <material name="white"> <color rgba="1 1 1 1"/> </material> <!--Base plate--> <link name="schunk_egp50_base_link"> <visual> <geometry> <cylinder length="0.015" radius="0.0375"/> </geometry> <material name="blue"/> <origin rpy="0 0 0" xyz="0 0 0.0075"/> </visual> <collision> <geometry> <cylinder length="0.015" radius="0.0375"/> </geometry> <origin rpy="0 0 0" xyz="0 0 0.0075"/> </collision> <inertial> <origin rpy="0 0 0" xyz="0 0 0.0075"/> <mass value="0.2"/> <inertia ixx="7.406249999999999e-05" ixy="0.0" ixz="0.0" iyy="7.406249999999999e-05" iyz="0.0" izz="0.000140625"/> </inertial> </link> <!--Main gripper--> <link name="schunk_egp50_body_link"> <visual> <geometry> <mesh filename="package://ur5e_cell_description/meshes/Gripper.stl" scale="0.001 0.001 0.001"/> </geometry> <origin rpy="1.5707963267948966 0 0" xyz="-0.025 0.015 -0.0433"/> <material name="green"/> </visual> <collision> <geometry> <mesh filename="package://ur5e_cell_description/meshes/Gripper.stl" scale="0.001 0.001 0.001"/> </geometry> <origin rpy="1.5707963267948966 0 0" xyz="-0.025 0.015 -0.0433"/> </collision> <inertial> <origin rpy="1.5707963267948966 0 0" xyz="-0.025 0.015 -0.0433"/> <mass value="0.5"/> <inertia ixx="0.00034998166666666666" ixy="0.0" ixz="0.0" iyy="0.00041664833333333336" iyz="0.0" izz="0.00014166666666666668"/> </inertial> </link> <!--Pincer block 1--> <link name="schunk_egp50_pincer_1_link"> <visual> <geometry> <mesh filename="package://ur5e_cell_description/meshes/Pincer_1.stl" scale="0.001 0.001 0.001"/> </geometry> <origin rpy="1.5707963267948966 0 0" xyz="-0.025 0.009 -0.0936"/> <material name="white"/> </visual> <collision> <geometry> <mesh filename="package://ur5e_cell_description/meshes/Pincer_1.stl" scale="0.001 0.001 0.001"/> </geometry> <origin rpy="1.5707963267948966 0 0" xyz="-0.025 0.009 -0.0936"/> </collision> <inertial> <origin rpy="1.5707963267948966 0 0" xyz="-0.025 0.009 -0.0936"/> <mass value="0.1"/> <inertia ixx="4.333333333333333e-06" ixy="0.0" ixz="0.0" iyy="2.246666666666667e-05" iyz="0.0" izz="2.3533333333333337e-05"/> </inertial> </link> <!--Pincer block 2--> <link name="schunk_egp50_pincer_2_link"> <visual> <geometry> <mesh filename="package://ur5e_cell_description/meshes/Pincer_2.stl" scale="0.001 0.001 0.001"/> </geometry> <origin rpy="1.5707963267948966 0 0" xyz="-0.025 0.009 -0.0936"/> <material name="blue"/> </visual> <collision> <geometry> <mesh filename="package://ur5e_cell_description/meshes/Pincer_2.stl" scale="0.001 0.001 0.001"/> </geometry> <origin rpy="1.5707963267948966 0 0" xyz="-0.025 0.009 -0.0936"/> </collision> <inertial> <origin rpy="1.5707963267948966 0 0" xyz="-0.025 0.009 -0.0936"/> <mass value="0.1"/> <inertia ixx="4.333333333333333e-06" ixy="0.0" ixz="0.0" iyy="2.246666666666667e-05" iyz="0.0" izz="2.3533333333333337e-05"/> </inertial> </link> <!-- Virtual link for visualizytion and planning--> <link name="tool_tip"/> <!-- Joints--> <joint name="schunk_egp50_body_joint" type="fixed"> <parent link="schunk_egp50_base_link"/> <child link="schunk_egp50_body_link"/> <origin rpy="0.0 0.0 0.0" xyz="0.0 0.0 0.0583"/> </joint> <joint name="schunk_egp50_pincer_1_joint" type="fixed"> <parent link="schunk_egp50_body_link"/> <child link="schunk_egp50_pincer_1_link"/> <origin rpy="0.0 0.0 0.0" xyz="0.0 0.0 0.0503"/> <!-- the motion of the pincer is along the X axis --> <axis xyz="1 0 0"/> <!-- the motion of the pincer is limited to the half of the gripper body length --> <limit effort="100" lower="-0.003125" upper="0.003125" velocity="100"/> </joint> <joint name="schunk_egp50_pincer_2_joint" type="fixed"> <parent link="schunk_egp50_body_link"/> <child link="schunk_egp50_pincer_2_link"/> <origin rpy="0.0 0.0 0.0" xyz="0.0 0.002 0.0503"/> <!-- the motion of the pincer is along the X axis --> <axis xyz="1 0 0"/> <!-- the motion of the pincer is limited to the half of the gripper body length --> <limit effort="100" lower="0.003125" upper="-0.003125" velocity="100"/> </joint> <joint name="schunk_egp50_tip_joint" type="fixed"> <parent link="schunk_egp50_base_link"/> <child link="tool_tip"/> <origin rpy="0.0 0.0 0.0" xyz="0 0 0.1044"/> </joint> <joint name="schunk_egp50_base_joint" type="fixed"> <parent link="tool0"/> <child link="schunk_egp50_base_link"/> <origin rpy="0 0 0" xyz="0 0 0"/> </joint> <!-- camera body, with origin at bottom screw mount --> <joint name="camera_joint" type="fixed"> <origin rpy="1.5707963267948966 -1.5707963267948966 0" xyz="0 -0.05 0"/> <parent link="tool0"/> <child link="camera_bottom_screw_frame"/> </joint> <link name="camera_bottom_screw_frame"/> <joint name="camera_link_joint" type="fixed"> <origin rpy="0 0 0" xyz="0.010600000000000002 0.0175 0.0125"/> <parent link="camera_bottom_screw_frame"/> <child link="camera_link"/> </joint> <link name="camera_link"> <visual> <!-- the mesh origin is at front plate in between the two infrared camera axes --> <origin rpy="1.5707963267948966 0 1.5707963267948966" xyz="0.0043 -0.0175 0"/> <geometry> <mesh filename="file:///home/admin326/workspaces/ros2_ws/install/realsense2_description/share/realsense2_description/meshes/d435.dae"/> </geometry> </visual> <collision> <origin rpy="0 0 0" xyz="0 -0.0175 0"/> <geometry> <box size="0.02505 0.09 0.025"/> </geometry> </collision> <inertial> <!-- The following are not reliable values, and should not be used for modeling --> <mass value="0.072"/> <origin xyz="0 0 0"/> <inertia ixx="0.003881243" ixy="0.0" ixz="0.0" iyy="0.000498940" iyz="0.0" izz="0.003879257"/> </inertial> </link> </robot>"
        "tf_prefix":
          type: String
          value: ""
        "update_rate":
          type: Integer
          value: 0
        "use_sim_time":
          type: Boolean
          value: False